[2018-04-25 21:02:44,699][Thread-298:7216][task_id:django.request][exception.py:135][ERROR][Internal Server Error: /app01/backend/add_article/]
Traceback (most recent call last):
  File "C:\Users\Administrator\AppData\Local\Programs\Python\Python35\lib\site-packages\django\template\base.py", line 507, in parse
    compile_func = self.tags[command]
KeyError: 'scrf_token'

During handling of the above exception, another exception occurred:

Traceback (most recent call last):
  File "C:\Users\Administrator\AppData\Local\Programs\Python\Python35\lib\site-packages\django\core\handlers\exception.py", line 41, in inner
    response = get_response(request)
  File "C:\Users\Administrator\AppData\Local\Programs\Python\Python35\lib\site-packages\django\core\handlers\base.py", line 187, in _get_response
    response = self.process_exception_by_middleware(e, request)
  File "C:\Users\Administrator\AppData\Local\Programs\Python\Python35\lib\site-packages\django\core\handlers\base.py", line 185, in _get_response
    response = wrapped_callback(request, *callback_args, **callback_kwargs)
  File "C:\Users\Administrator\PycharmProjects\cnblogs\app01\views.py", line 314, in add_article
    return render(request, "add_article.html")
  File "C:\Users\Administrator\AppData\Local\Programs\Python\Python35\lib\site-packages\django\shortcuts.py", line 30, in render
    content = loader.render_to_string(template_name, context, request, using=using)
  File "C:\Users\Administrator\AppData\Local\Programs\Python\Python35\lib\site-packages\django\template\loader.py", line 67, in render_to_string
    template = get_template(template_name, using=using)
  File "C:\Users\Administrator\AppData\Local\Programs\Python\Python35\lib\site-packages\django\template\loader.py", line 21, in get_template
    return engine.get_template(template_name)
  File "C:\Users\Administrator\AppData\Local\Programs\Python\Python35\lib\site-packages\django\template\backends\django.py", line 39, in get_template
    return Template(self.engine.get_template(template_name), self)
  File "C:\Users\Administrator\AppData\Local\Programs\Python\Python35\lib\site-packages\django\template\engine.py", line 162, in get_template
    template, origin = self.find_template(template_name)
  File "C:\Users\Administrator\AppData\Local\Programs\Python\Python35\lib\site-packages\django\template\engine.py", line 136, in find_template
    name, template_dirs=dirs, skip=skip,
  File "C:\Users\Administrator\AppData\Local\Programs\Python\Python35\lib\site-packages\django\template\loaders\base.py", line 44, in get_template
    contents, origin, origin.template_name, self.engine,
  File "C:\Users\Administrator\AppData\Local\Programs\Python\Python35\lib\site-packages\django\template\base.py", line 191, in __init__
    self.nodelist = self.compile_nodelist()
  File "C:\Users\Administrator\AppData\Local\Programs\Python\Python35\lib\site-packages\django\template\base.py", line 230, in compile_nodelist
    return parser.parse()
  File "C:\Users\Administrator\AppData\Local\Programs\Python\Python35\lib\site-packages\django\template\base.py", line 515, in parse
    raise self.error(token, e)
  File "C:\Users\Administrator\AppData\Local\Programs\Python\Python35\lib\site-packages\django\template\base.py", line 513, in parse
    compiled_result = compile_func(self, token)
  File "C:\Users\Administrator\AppData\Local\Programs\Python\Python35\lib\site-packages\django\template\loader_tags.py", line 312, in do_extends
    nodelist = parser.parse()
  File "C:\Users\Administrator\AppData\Local\Programs\Python\Python35\lib\site-packages\django\template\base.py", line 515, in parse
    raise self.error(token, e)
  File "C:\Users\Administrator\AppData\Local\Programs\Python\Python35\lib\site-packages\django\template\base.py", line 513, in parse
    compiled_result = compile_func(self, token)
  File "C:\Users\Administrator\AppData\Local\Programs\Python\Python35\lib\site-packages\django\template\loader_tags.py", line 255, in do_block
    nodelist = parser.parse(('endblock',))
  File "C:\Users\Administrator\AppData\Local\Programs\Python\Python35\lib\site-packages\django\template\base.py", line 509, in parse
    self.invalid_block_tag(token, command, parse_until)
  File "C:\Users\Administrator\AppData\Local\Programs\Python\Python35\lib\site-packages\django\template\base.py", line 565, in invalid_block_tag
    get_text_list(["'%s'" % p for p in parse_until], 'or'),
django.template.exceptions.TemplateSyntaxError: Invalid block tag on line 9: 'scrf_token', expected 'endblock'. Did you forget to register or load this tag?
[2018-04-25 21:03:12,663][Thread-306:4636][task_id:django.request][exception.py:135][ERROR][Internal Server Error: /app01/backend/add_article/]
Traceback (most recent call last):
  File "C:\Users\Administrator\AppData\Local\Programs\Python\Python35\lib\site-packages\django\core\handlers\exception.py", line 41, in inner
    response = get_response(request)
  File "C:\Users\Administrator\AppData\Local\Programs\Python\Python35\lib\site-packages\django\core\handlers\base.py", line 187, in _get_response
    response = self.process_exception_by_middleware(e, request)
  File "C:\Users\Administrator\AppData\Local\Programs\Python\Python35\lib\site-packages\django\core\handlers\base.py", line 185, in _get_response
    response = wrapped_callback(request, *callback_args, **callback_kwargs)
  File "C:\Users\Administrator\PycharmProjects\cnblogs\app01\views.py", line 300, in add_article
    soup = BeautifulSoup(article_con, "html.parser")
  File "C:\Users\Administrator\AppData\Roaming\Python\Python35\site-packages\bs4\__init__.py", line 192, in __init__
    elif len(markup) <= 256 and (
TypeError: object of type 'NoneType' has no len()
[2018-04-25 21:05:03,697][Thread-307:1276][task_id:django.request][exception.py:135][ERROR][Internal Server Error: /app01/backend/add_article/]
Traceback (most recent call last):
  File "C:\Users\Administrator\AppData\Local\Programs\Python\Python35\lib\site-packages\django\core\handlers\exception.py", line 41, in inner
    response = get_response(request)
  File "C:\Users\Administrator\AppData\Local\Programs\Python\Python35\lib\site-packages\django\core\handlers\base.py", line 187, in _get_response
    response = self.process_exception_by_middleware(e, request)
  File "C:\Users\Administrator\AppData\Local\Programs\Python\Python35\lib\site-packages\django\core\handlers\base.py", line 185, in _get_response
    response = wrapped_callback(request, *callback_args, **callback_kwargs)
  File "C:\Users\Administrator\PycharmProjects\cnblogs\app01\views.py", line 300, in add_article
    soup = BeautifulSoup(article_con, "html.parser")
  File "C:\Users\Administrator\AppData\Roaming\Python\Python35\site-packages\bs4\__init__.py", line 192, in __init__
    elif len(markup) <= 256 and (
TypeError: object of type 'NoneType' has no len()
[2018-04-25 21:05:17,636][Thread-308:7220][task_id:django.request][exception.py:135][ERROR][Internal Server Error: /app01/backend/add_article/]
Traceback (most recent call last):
  File "C:\Users\Administrator\AppData\Local\Programs\Python\Python35\lib\site-packages\django\core\handlers\exception.py", line 41, in inner
    response = get_response(request)
  File "C:\Users\Administrator\AppData\Local\Programs\Python\Python35\lib\site-packages\django\core\handlers\base.py", line 187, in _get_response
    response = self.process_exception_by_middleware(e, request)
  File "C:\Users\Administrator\AppData\Local\Programs\Python\Python35\lib\site-packages\django\core\handlers\base.py", line 185, in _get_response
    response = wrapped_callback(request, *callback_args, **callback_kwargs)
  File "C:\Users\Administrator\PycharmProjects\cnblogs\app01\views.py", line 300, in add_article
    soup = BeautifulSoup(article_con, "html.parser")
  File "C:\Users\Administrator\AppData\Roaming\Python\Python35\site-packages\bs4\__init__.py", line 192, in __init__
    elif len(markup) <= 256 and (
TypeError: object of type 'NoneType' has no len()
[2018-04-25 21:06:08,925][Thread-1:5292][task_id:django.request][exception.py:135][ERROR][Internal Server Error: /app01/backend/add_article/]
Traceback (most recent call last):
  File "C:\Users\Administrator\AppData\Local\Programs\Python\Python35\lib\site-packages\django\core\handlers\exception.py", line 41, in inner
    response = get_response(request)
  File "C:\Users\Administrator\AppData\Local\Programs\Python\Python35\lib\site-packages\django\core\handlers\base.py", line 187, in _get_response
    response = self.process_exception_by_middleware(e, request)
  File "C:\Users\Administrator\AppData\Local\Programs\Python\Python35\lib\site-packages\django\core\handlers\base.py", line 185, in _get_response
    response = wrapped_callback(request, *callback_args, **callback_kwargs)
  File "C:\Users\Administrator\PycharmProjects\cnblogs\app01\views.py", line 300, in add_article
    soup = BeautifulSoup(article_con, "html.parser")
  File "C:\Users\Administrator\AppData\Roaming\Python\Python35\site-packages\bs4\__init__.py", line 192, in __init__
    elif len(markup) <= 256 and (
TypeError: object of type 'NoneType' has no len()
[2018-04-25 21:09:24,208][Thread-3:8652][task_id:django.request][exception.py:135][ERROR][Internal Server Error: /app01/backend/add_article/]
Traceback (most recent call last):
  File "C:\Users\Administrator\AppData\Local\Programs\Python\Python35\lib\site-packages\django\core\handlers\exception.py", line 41, in inner
    response = get_response(request)
  File "C:\Users\Administrator\AppData\Local\Programs\Python\Python35\lib\site-packages\django\core\handlers\base.py", line 187, in _get_response
    response = self.process_exception_by_middleware(e, request)
  File "C:\Users\Administrator\AppData\Local\Programs\Python\Python35\lib\site-packages\django\core\handlers\base.py", line 185, in _get_response
    response = wrapped_callback(request, *callback_args, **callback_kwargs)
  File "C:\Users\Administrator\PycharmProjects\cnblogs\app01\views.py", line 300, in add_article
    soup = BeautifulSoup(article_con, "html.parser")
  File "C:\Users\Administrator\AppData\Roaming\Python\Python35\site-packages\bs4\__init__.py", line 192, in __init__
    elif len(markup) <= 256 and (
TypeError: object of type 'NoneType' has no len()
[2018-04-25 21:09:51,201][Thread-5:9072][task_id:django.request][exception.py:135][ERROR][Internal Server Error: /app01/backend/add_article/]
Traceback (most recent call last):
  File "C:\Users\Administrator\AppData\Local\Programs\Python\Python35\lib\site-packages\django\core\handlers\exception.py", line 41, in inner
    response = get_response(request)
  File "C:\Users\Administrator\AppData\Local\Programs\Python\Python35\lib\site-packages\django\core\handlers\base.py", line 187, in _get_response
    response = self.process_exception_by_middleware(e, request)
  File "C:\Users\Administrator\AppData\Local\Programs\Python\Python35\lib\site-packages\django\core\handlers\base.py", line 185, in _get_response
    response = wrapped_callback(request, *callback_args, **callback_kwargs)
  File "C:\Users\Administrator\PycharmProjects\cnblogs\app01\views.py", line 300, in add_article
    soup = BeautifulSoup(article_con, "html.parser")
  File "C:\Users\Administrator\AppData\Roaming\Python\Python35\site-packages\bs4\__init__.py", line 192, in __init__
    elif len(markup) <= 256 and (
TypeError: object of type 'NoneType' has no len()
[2018-04-25 21:12:29,977][Thread-6:4688][task_id:django.request][exception.py:135][ERROR][Internal Server Error: /app01/backend/add_article/]
Traceback (most recent call last):
  File "C:\Users\Administrator\AppData\Local\Programs\Python\Python35\lib\site-packages\django\core\handlers\exception.py", line 41, in inner
    response = get_response(request)
  File "C:\Users\Administrator\AppData\Local\Programs\Python\Python35\lib\site-packages\django\core\handlers\base.py", line 187, in _get_response
    response = self.process_exception_by_middleware(e, request)
  File "C:\Users\Administrator\AppData\Local\Programs\Python\Python35\lib\site-packages\django\core\handlers\base.py", line 185, in _get_response
    response = wrapped_callback(request, *callback_args, **callback_kwargs)
  File "C:\Users\Administrator\PycharmProjects\cnblogs\app01\views.py", line 300, in add_article
    soup = BeautifulSoup(article_con, "html.parser")
  File "C:\Users\Administrator\AppData\Roaming\Python\Python35\site-packages\bs4\__init__.py", line 192, in __init__
    elif len(markup) <= 256 and (
TypeError: object of type 'NoneType' has no len()
[2018-04-25 21:15:43,930][Thread-4:4544][task_id:django.request][exception.py:135][ERROR][Internal Server Error: /app01/backend/add_article/]
Traceback (most recent call last):
  File "C:\Users\Administrator\AppData\Local\Programs\Python\Python35\lib\site-packages\django\db\backends\utils.py", line 64, in execute
    return self.cursor.execute(sql, params)
  File "C:\Users\Administrator\AppData\Local\Programs\Python\Python35\lib\site-packages\django\db\backends\mysql\base.py", line 101, in execute
    return self.cursor.execute(query, args)
  File "C:\Users\Administrator\AppData\Local\Programs\Python\Python35\lib\site-packages\pymysql\cursors.py", line 165, in execute
    result = self._query(query)
  File "C:\Users\Administrator\AppData\Local\Programs\Python\Python35\lib\site-packages\pymysql\cursors.py", line 321, in _query
    conn.query(q)
  File "C:\Users\Administrator\AppData\Local\Programs\Python\Python35\lib\site-packages\pymysql\connections.py", line 860, in query
    self._affected_rows = self._read_query_result(unbuffered=unbuffered)
  File "C:\Users\Administrator\AppData\Local\Programs\Python\Python35\lib\site-packages\pymysql\connections.py", line 1061, in _read_query_result
    result.read()
  File "C:\Users\Administrator\AppData\Local\Programs\Python\Python35\lib\site-packages\pymysql\connections.py", line 1349, in read
    first_packet = self.connection._read_packet()
  File "C:\Users\Administrator\AppData\Local\Programs\Python\Python35\lib\site-packages\pymysql\connections.py", line 1018, in _read_packet
    packet.check_error()
  File "C:\Users\Administrator\AppData\Local\Programs\Python\Python35\lib\site-packages\pymysql\connections.py", line 384, in check_error
    err.raise_mysql_exception(self._data)
  File "C:\Users\Administrator\AppData\Local\Programs\Python\Python35\lib\site-packages\pymysql\err.py", line 107, in raise_mysql_exception
    raise errorclass(errno, errval)
pymysql.err.IntegrityError: (1048, "Column 'create_time' cannot be null")

The above exception was the direct cause of the following exception:

Traceback (most recent call last):
  File "C:\Users\Administrator\AppData\Local\Programs\Python\Python35\lib\site-packages\django\core\handlers\exception.py", line 41, in inner
    response = get_response(request)
  File "C:\Users\Administrator\AppData\Local\Programs\Python\Python35\lib\site-packages\django\core\handlers\base.py", line 187, in _get_response
    response = self.process_exception_by_middleware(e, request)
  File "C:\Users\Administrator\AppData\Local\Programs\Python\Python35\lib\site-packages\django\core\handlers\base.py", line 185, in _get_response
    response = wrapped_callback(request, *callback_args, **callback_kwargs)
  File "C:\Users\Administrator\PycharmProjects\cnblogs\app01\views.py", line 310, in add_article
    article_obj = Article.objects.create(title=title, user=request.user, desc=soup.text[0:150])
  File "C:\Users\Administrator\AppData\Local\Programs\Python\Python35\lib\site-packages\django\db\models\manager.py", line 85, in manager_method
    return getattr(self.get_queryset(), name)(*args, **kwargs)
  File "C:\Users\Administrator\AppData\Local\Programs\Python\Python35\lib\site-packages\django\db\models\query.py", line 394, in create
    obj.save(force_insert=True, using=self.db)
  File "C:\Users\Administrator\AppData\Local\Programs\Python\Python35\lib\site-packages\django\db\models\base.py", line 808, in save
    force_update=force_update, update_fields=update_fields)
  File "C:\Users\Administrator\AppData\Local\Programs\Python\Python35\lib\site-packages\django\db\models\base.py", line 838, in save_base
    updated = self._save_table(raw, cls, force_insert, force_update, using, update_fields)
  File "C:\Users\Administrator\AppData\Local\Programs\Python\Python35\lib\site-packages\django\db\models\base.py", line 924, in _save_table
    result = self._do_insert(cls._base_manager, using, fields, update_pk, raw)
  File "C:\Users\Administrator\AppData\Local\Programs\Python\Python35\lib\site-packages\django\db\models\base.py", line 963, in _do_insert
    using=using, raw=raw)
  File "C:\Users\Administrator\AppData\Local\Programs\Python\Python35\lib\site-packages\django\db\models\manager.py", line 85, in manager_method
    return getattr(self.get_queryset(), name)(*args, **kwargs)
  File "C:\Users\Administrator\AppData\Local\Programs\Python\Python35\lib\site-packages\django\db\models\query.py", line 1076, in _insert
    return query.get_compiler(using=using).execute_sql(return_id)
  File "C:\Users\Administrator\AppData\Local\Programs\Python\Python35\lib\site-packages\django\db\models\sql\compiler.py", line 1112, in execute_sql
    cursor.execute(sql, params)
  File "C:\Users\Administrator\AppData\Local\Programs\Python\Python35\lib\site-packages\django\db\backends\utils.py", line 79, in execute
    return super(CursorDebugWrapper, self).execute(sql, params)
  File "C:\Users\Administrator\AppData\Local\Programs\Python\Python35\lib\site-packages\django\db\backends\utils.py", line 64, in execute
    return self.cursor.execute(sql, params)
  File "C:\Users\Administrator\AppData\Local\Programs\Python\Python35\lib\site-packages\django\db\utils.py", line 94, in __exit__
    six.reraise(dj_exc_type, dj_exc_value, traceback)
  File "C:\Users\Administrator\AppData\Local\Programs\Python\Python35\lib\site-packages\django\utils\six.py", line 685, in reraise
    raise value.with_traceback(tb)
  File "C:\Users\Administrator\AppData\Local\Programs\Python\Python35\lib\site-packages\django\db\backends\utils.py", line 64, in execute
    return self.cursor.execute(sql, params)
  File "C:\Users\Administrator\AppData\Local\Programs\Python\Python35\lib\site-packages\django\db\backends\mysql\base.py", line 101, in execute
    return self.cursor.execute(query, args)
  File "C:\Users\Administrator\AppData\Local\Programs\Python\Python35\lib\site-packages\pymysql\cursors.py", line 165, in execute
    result = self._query(query)
  File "C:\Users\Administrator\AppData\Local\Programs\Python\Python35\lib\site-packages\pymysql\cursors.py", line 321, in _query
    conn.query(q)
  File "C:\Users\Administrator\AppData\Local\Programs\Python\Python35\lib\site-packages\pymysql\connections.py", line 860, in query
    self._affected_rows = self._read_query_result(unbuffered=unbuffered)
  File "C:\Users\Administrator\AppData\Local\Programs\Python\Python35\lib\site-packages\pymysql\connections.py", line 1061, in _read_query_result
    result.read()
  File "C:\Users\Administrator\AppData\Local\Programs\Python\Python35\lib\site-packages\pymysql\connections.py", line 1349, in read
    first_packet = self.connection._read_packet()
  File "C:\Users\Administrator\AppData\Local\Programs\Python\Python35\lib\site-packages\pymysql\connections.py", line 1018, in _read_packet
    packet.check_error()
  File "C:\Users\Administrator\AppData\Local\Programs\Python\Python35\lib\site-packages\pymysql\connections.py", line 384, in check_error
    err.raise_mysql_exception(self._data)
  File "C:\Users\Administrator\AppData\Local\Programs\Python\Python35\lib\site-packages\pymysql\err.py", line 107, in raise_mysql_exception
    raise errorclass(errno, errval)
django.db.utils.IntegrityError: (1048, "Column 'create_time' cannot be null")
